Traceback (most recent call last):
  File "/Users/Terru/opt/miniconda3/envs/moe-kit/lib/python3.11/site-packages/wandb/sdk/wandb_config.py", line 162, in __getattr__
    return self.__getitem__(key)
           ^^^^^^^^^^^^^^^^^^^^^
  File "/Users/Terru/opt/miniconda3/envs/moe-kit/lib/python3.11/site-packages/wandb/sdk/wandb_config.py", line 130, in __getitem__
    return self._items[key]
           ~~~~~~~~~~~^^^^^
KeyError: 'parameters'
The above exception was the direct cause of the following exception:
Traceback (most recent call last):
  File "/var/folders/2g/tp6k18_n7cs15v8fpv2dc56w0000gn/T/ipykernel_1927/662660863.py", line 28, in train
    config = wandb.config.parameters
             ^^^^^^^^^^^^^^^^^^^^^^^
  File "/Users/Terru/opt/miniconda3/envs/moe-kit/lib/python3.11/site-packages/wandb/sdk/wandb_config.py", line 164, in __getattr__
    raise AttributeError(
AttributeError: <class 'wandb.sdk.wandb_config.Config'> object has no attribute 'parameters'